Workbook

Sheet Scorecard
A1: NovaDrive supplier risk scorecard: six-dimension model
A2: All scores run 0-100 where 100 = riskiest. Overall % = weighted average of the six dimension scores (weights editable on 'Scales'). Missing data is penalised in D6, never treated as low risk. Network and evidence come from the tiering workbook (confirmed and inferred links only). Built only from the supplied workbook.
A4: Rank | B4: Entity ID | C4: Legal name | D4: Tier | E4: Link status | F4: D1 Financial & operational | G4: D2 Location & systemic | H4: D3 Network dependence | I4: D4 Criticality & substitutability | J4: D5 External threats | K4: D6 Information gap | L4: OVERALL RISK % | M4: Band | N4: Confidence | O4: Key vulnerability driver | P4: Next step
A5: =Calc!AV2 -> 1 | B5: =Calc!A2 -> ORG-453 | C5: =Calc!B2 -> Jade Printed Circuits Ltd. | D5: =Calc!C2 -> Tier-2 | E5: =Calc!D2 -> Confirmed | F5: =Calc!AH2 -> 40.90281 | G5: =Calc!AI2 -> 76.333333 | H5: =Calc!AJ2 -> 100 | I5: =Calc!AK2 -> 87.5 | J5: =Calc!AL2 -> 40 | K5: =Calc!AM2 -> 22.5 | L5: =Calc!AN2 -> 69.005562 | M5: =Calc!AQ2 -> High | N5: =Calc!AT2 -> High | O5: Network dependence & upstream concentration: an outage hits 3 Tier-1 suppliers; 100% of component supply routed via it; no second qualified source (DOC-079) | Location & systemic exposure: zone Z01: hazard 82, logistics 76, infrastructure 71 | P5: =Calc!AU2 -> Search alternates now
A6: =Calc!AV3 -> 2 | B6: =Calc!A3 -> ORG-455 | C6: =Calc!B3 -> Umber Silicon Carbide Ltd. | D6: =Calc!C3 -> Tier-3 | E6: =Calc!D3 -> Confirmed | F6: =Calc!AH3 -> 48.856209 | G6: =Calc!AI3 -> 76.333333 | H6: =Calc!AJ3 -> 66.666667 | I6: =Calc!AK3 -> 100 | J6: =Calc!AL3 -> 40 | K6: =Calc!AM3 -> 68.75 | L6: =Calc!AN3 -> 67.096242 | M6: =Calc!AQ3 -> High | N6: =Calc!AT3 -> Low | O6: Location & systemic exposure: zone Z01: hazard 82, logistics 76, infrastructure 71 | Business criticality & substitutability: reaches P1+P2+P3 = USD 1,560m (100% of revenue); 16-week replacement | P6: =Calc!AU3 -> Verify data first
A7: =Calc!AV4 -> 3 | B7: =Calc!A4 -> ORG-736 | C7: =Calc!B4 -> Verdant Process Gases Ltd. | D7: =Calc!C4 -> Tier-3 | E7: =Calc!D4 -> Inferred | F7: =Calc!AH4 -> 41.094771 | G7: =Calc!AI4 -> 76.333333 | H7: =Calc!AJ4 -> 66.666667 | I7: =Calc!AK4 -> 100 | J7: =Calc!AL4 -> 40 | K7: =Calc!AM4 -> 68.75 | L7: =Calc!AN4 -> 65.543954 | M7: =Calc!AQ4 -> High | N7: =Calc!AT4 -> Low | O7: Location & systemic exposure: zone Z01: hazard 82, logistics 76, infrastructure 71 | Business criticality & substitutability: reaches P1+P2+P3 = USD 1,560m (100% of revenue); 16-week replacement | P7: =Calc!AU4 -> Verify the link first (needs direct disclosure)
A8: =Calc!AV5 -> 4 | B8: =Calc!A5 -> ORG-439 | C8: =Calc!B5 -> IonPeak Semiconductor Ltd. | D8: =Calc!C5 -> Tier-2 | E8: =Calc!D5 -> Confirmed | F8: =Calc!AH5 -> 40.036736 | G8: =Calc!AI5 -> 76.333333 | H8: =Calc!AJ5 -> 83.333333 | I8: =Calc!AK5 -> 100 | J8: =Calc!AL5 -> 40 | K8: =Calc!AM5 -> 18 | L8: =Calc!AN5 -> 65.257347 | M8: =Calc!AQ5 -> High | N8: =Calc!AT5 -> High | O8: Network dependence & upstream concentration: an outage hits 2 Tier-1 suppliers; 100% of component supply routed via it; no second qualified source (DOC-078) | Location & systemic exposure: zone Z01: hazard 82, logistics 76, infrastructure 71 | P8: =Calc!AU5 -> Search alternates now
A9: =Calc!AV6 -> 5 | B9: =Calc!A6 -> ORG-708 | C9: =Calc!B6 -> Orion Ceramics Ltd. | D9: =Calc!C6 -> Tier-2 | E9: =Calc!D6 -> Confirmed | F9: =Calc!AH6 -> 27.971637 | G9: =Calc!AI6 -> 76.333333 | H9: =Calc!AJ6 -> 66.666667 | I9: =Calc!AK6 -> 100 | J9: =Calc!AL6 -> 40 | K9: =Calc!AM6 -> 15 | L9: =Calc!AN6 -> 57.544327 | M9: =Calc!AQ6 -> High | N9: =Calc!AT6 -> Medium | O9: Location & systemic exposure: zone Z01: hazard 82, logistics 76, infrastructure 71 | Business criticality & substitutability: reaches P1+P2+P3 = USD 1,560m (100% of revenue); 16-week replacement | P9: =Calc!AU6 -> Search alternates now
A10: =Calc!AV7 -> 6 | B10: =Calc!A7 -> ORG-210 | C10: =Calc!B7 -> Meridian Dielectrics Ltd. | D10: =Calc!C7 -> Tier-2 | E10: =Calc!D7 -> Confirmed | F10: =Calc!AH7 -> 100 | G10: =Calc!AI7 -> 23.333333 | H10: =Calc!AJ7 -> 50 | I10: =Calc!AK7 -> 61.666667 | J10: =Calc!AL7 -> 60 | K10: =Calc!AM7 -> 36 | L10: =Calc!AN7 -> 57.35 | M10: =Calc!AQ7 -> High | N10: =Calc!AT7 -> Medium | O10: Financial & operational health: current ratio 0.62, debt/EBITDA 7.2, on-time 76.4% (-17.6 pts since Jan) | Dynamic external threats: EV-003 financing pressure (production continues) | P10: =Calc!AU7 -> Search alternates now
A11: =Calc!AV8 -> 7 | B11: =Calc!A8 -> ORG-873 | C11: =Calc!B8 -> Warden Copper Foil Ltd. | D11: =Calc!C8 -> Tier-3 | E11: =Calc!D8 -> Confirmed | F11: =Calc!AH8 -> 16.503268 | G11: =Calc!AI8 -> 60 | H11: =Calc!AJ8 -> 83.333333 | I11: =Calc!AK8 -> 87.5 | J11: =Calc!AL8 -> 0 | K11: =Calc!AM8 -> 68.75 | L11: =Calc!AN8 -> 57.300654 | M11: =Calc!AQ8 -> High | N11: =Calc!AT8 -> Low | O11: Network dependence & upstream concentration: an outage hits 3 Tier-1 suppliers; 100% of component supply routed via it; no alternative stated in data | Information gap & assurance: assurance gap not in data (scored 100); 3 of 8 indicator fields missing | P11: =Calc!AU8 -> Verify data first
A12: =Calc!AV9 -> 8 | B12: =Calc!A9 -> ORG-179 | C12: =Calc!B9 -> Xenon Resin Ltd. | D12: =Calc!C9 -> Tier-3 | E12: =Calc!D9 -> Confirmed | F12: =Calc!AH9 -> 16.830065 | G12: =Calc!AI9 -> 57.333333 | H12: =Calc!AJ9 -> 83.333333 | I12: =Calc!AK9 -> 87.5 | J12: =Calc!AL9 -> 0 | K12: =Calc!AM9 -> 68.75 | L12: =Calc!AN9 -> 56.966013 | M12: =Calc!AQ9 -> High | N12: =Calc!AT9 -> Low | O12: Network dependence & upstream concentration: an outage hits 3 Tier-1 suppliers; 100% of component supply routed via it; no alternative stated in data | Information gap & assurance: assurance gap not in data (scored 100); 3 of 8 indicator fields missing | P12: =Calc!AU9 -> Verify data first
A13: =Calc!AV10 -> 9 | B13: =Calc!A10 -> ORG-942 | C13: =Calc!B10 -> Lumen Magnetics Ltd. | D13: =Calc!C10 -> Tier-2 | E13: =Calc!D10 -> Confirmed | F13: =Calc!AH10 -> 31.0092 | G13: =Calc!AI10 -> 57.333333 | H13: =Calc!AJ10 -> 66.666667 | I13: =Calc!AK10 -> 100 | J13: =Calc!AL10 -> 0 | K13: =Calc!AM10 -> 31.5 | L13: =Calc!AN10 -> 52.95184 | M13: =Calc!AQ10 -> Medium | N13: =Calc!AT10 -> Medium | O13: Business criticality & substitutability: reaches P1+P2+P3 = USD 1,560m (100% of revenue); 16-week replacement | Network dependence & upstream concentration: an outage hits 2 Tier-1 suppliers; 100% of component supply routed via it; no alternative stated in data | P13: =Calc!AU10 -> Prepare shortlist and monitor
A14: =Calc!AV11 -> 10 | B14: =Calc!A11 -> ORG-520 | C14: =Calc!B11 -> Yarrow Specialty Minerals Ltd. | D14: =Calc!C11 -> Tier-3 | E14: =Calc!D11 -> Confirmed | F14: =Calc!AH11 -> 15.03268 | G14: =Calc!AI11 -> 42.333333 | H14: =Calc!AJ11 -> 66.666667 | I14: =Calc!AK11 -> 100 | J14: =Calc!AL11 -> 0 | K14: =Calc!AM11 -> 68.75 | L14: =Calc!AN11 -> 51.231536 | M14: =Calc!AQ11 -> Medium | N14: =Calc!AT11 -> Low | O14: Business criticality & substitutability: reaches P1+P2+P3 = USD 1,560m (100% of revenue); 16-week replacement | Information gap & assurance: assurance gap not in data (scored 100); 3 of 8 indicator fields missing | P14: =Calc!AU11 -> Prepare shortlist and monitor
A15: =Calc!AV12 -> 11 | B15: =Calc!A12 -> ORG-119 | C15: =Calc!B12 -> Cobalt Control Electronics Ltd. | D15: =Calc!C12 -> Tier-1 | E15: =Calc!D12 -> Confirmed | F15: =Calc!AH12 -> 34.559175 | G15: =Calc!AI12 -> 57.333333 | H15: =Calc!AJ12 -> 66.666667 | I15: =Calc!AK12 -> 87.5 | J15: =Calc!AL12 -> 0 | K15: =Calc!AM12 -> 21 | L15: =Calc!AN12 -> 50.736835 | M15: =Calc!AQ12 -> Medium | N15: =Calc!AT12 -> High | O15: Network dependence & upstream concentration: an outage hits 1 Tier-1 supplier; 100% of component supply routed via it; sole disclosed Tier-1 (100%) | Business criticality & substitutability: reaches P1+P2+P3 = USD 1,560m (100% of revenue); 12-week replacement | P15: =Calc!AU12 -> Prepare shortlist and monitor
A16: =Calc!AV13 -> 12 | B16: =Calc!A13 -> ORG-728 | C16: =Calc!B13 -> Kestrel Microdevices Ltd. | D16: =Calc!C13 -> Tier-2 | E16: =Calc!D13 -> Confirmed | F16: =Calc!AH13 -> 21.462022 | G16: =Calc!AI13 -> 24.333333 | H16: =Calc!AJ13 -> 66.666667 | I16: =Calc!AK13 -> 87.5 | J16: =Calc!AL13 -> 0 | K16: =Calc!AM13 -> 27 | L16: =Calc!AN13 -> 43.767404 | M16: =Calc!AQ13 -> Medium | N16: =Calc!AT13 -> Medium | O16: Network dependence & upstream concentration: an outage hits 2 Tier-1 suppliers; 100% of component supply routed via it; no alternative stated in data | Business criticality & substitutability: reaches P1+P2+P3 = USD 1,560m (100% of revenue); 12-week replacement | P16: =Calc!AU13 -> Prepare shortlist and monitor
... A28: =Calc!AV25 -> 24 | B28: =Calc!A25 -> ORG-176 | C28: =Calc!B25 -> HarborSense Electronics Ltd. | D28: =Calc!C25 -> Tier-1 | E28: =Calc!D25 -> Confirmed | F28: =Calc!AH25 -> 29.7061 | G28: =Calc!AI25 -> 24.333333 | H28: =Calc!AJ25 -> 6.6666667 | I28: =Calc!AK25 -> 50.833333 | J28: =Calc!AL25 -> 0 | K28: =Calc!AM25 -> 13.5 | L28: =Calc!AN25 -> 20.56622 | M28: =Calc!AQ25 -> Low | N28: =Calc!AT25 -> High | O28: No dimension above the network average; highest is Business criticality & substitutability: reaches P3 = USD 416m (27% of revenue); 12-week replacement | P28: =Calc!AU25 -> Monitor
A30: Key vulnerability driver = the two dimensions where the supplier sits furthest above the network average (weighted). Rows are sorted by Overall % under the active weights.
A31: Not scored: hypotheses (Solace Optics, Alder Bauxite) and non-supplier entities (CommonSpan, Jade Holdings, Harbor Freight, Ion Peak Trading, Delta Consumer Plastics): see the tiering workbook.

Sheet Network Map
A1: Product | B1: Component | C1: Tier-1 supplier (disclosed allocation) | D1: Tier-2 supplier | E1: Tier-3 supplier | F1: Path status (weakest link) | G1: Evidence IDs: Tier-1 | Tier-2 | Tier-3
A2: P1 DriveCore | B2: C10 Control board | C2: Cobalt Control Electronics Ltd. (100%) | D2: Jade Printed Circuits Ltd. | E2: Warden Copper Foil Ltd. | F2: Confirmed | G2: DOC-009, DOC-010, SHP-00050 | DOC-025, DOC-079 | DOC-060
A3: P1 DriveCore | B3: C10 Control board | C3: Cobalt Control Electronics Ltd. (100%) | D3: Jade Printed Circuits Ltd. | E3: Xenon Resin Ltd. | F3: Confirmed | G3: DOC-009, DOC-010, SHP-00050 | DOC-025, DOC-079 | DOC-064
A4: P1 DriveCore | B4: C10 Control board | C4: Cobalt Control Electronics Ltd. (100%) | D4: Kestrel Microdevices Ltd. | E4: - | F4: Confirmed | G4: DOC-009, DOC-010, SHP-00050 | DOC-031
A5: P1 DriveCore | B5: C10 Control board | C5: Cobalt Control Electronics Ltd. (100%) | D5: Rill Connectors Ltd. | E5: - | F5: Confirmed | G5: DOC-009, DOC-010, SHP-00050 | DOC-051
A6: P1 DriveCore | B6: C20 DC-link capacitor | C6: Delta Capacitor Works Ltd. (100%) | D6: Meridian Dielectrics Ltd. | E6: Zenith Polymer Ltd. | F6: Confirmed | G6: DOC-011, DOC-012, SHP-00062 | DOC-039 | DOC-070
A7: P1 DriveCore | B7: C20 DC-link capacitor | C7: Delta Capacitor Works Ltd. (100%) | D7: Nacre Foils Ltd. | E7: - | F7: Confirmed | G7: DOC-011, DOC-012, SHP-00062 | DOC-041
A8: P1 DriveCore | B8: H10 Protective housing | C8: ForgeLine Enclosures Ltd. (100%) | D8: Quartz Alloy Ltd. | E8: - | F8: Confirmed | G8: DOC-015, DOC-016 | DOC-049
A9: P1 DriveCore | B9: M10 Standard power assembly | C9: Aster Power Assemblies Ltd. (60%) | D9: IonPeak Semiconductor Ltd. | E9: Umber Silicon Carbide Ltd. | F9: Confirmed | G9: DOC-001, DOC-002, SHP-00002 | DOC-021, DOC-078 | DOC-056
A10: P1 DriveCore | B10: M10 Standard power assembly | C10: Aster Power Assemblies Ltd. (60%) | D10: IonPeak Semiconductor Ltd. | E10: Verdant Process Gases Ltd. | F10: Inferred | G10: DOC-001, DOC-002, SHP-00002 | DOC-021, DOC-078 | DOC-058
A11: P1 DriveCore | B11: M10 Standard power assembly | C11: Aster Power Assemblies Ltd. (60%) | D11: Lumen Magnetics Ltd. | E11: - | F11: Confirmed | G11: DOC-001, DOC-002, SHP-00002 | DOC-035
A12: P1 DriveCore | B12: M10 Standard power assembly | C12: Aster Power Assemblies Ltd. (60%) | D12: Orion Ceramics Ltd. | E12: Yarrow Specialty Minerals Ltd. | F12: Confirmed | G12: DOC-001, DOC-002, SHP-00002 | DOC-043 | DOC-066
... A49: P3 StoreLink | B49: M10 Standard power assembly | C49: Boreal Power Systems Ltd. (40%) | D49: Orion Ceramics Ltd. | E49: Yarrow Specialty Minerals Ltd. | F49: Confirmed | G49: DOC-005, DOC-006, SHP-00025 | DOC-045 | DOC-066
A51: 48 paths from the confirmed and inferred links in the tiering workbook ('Network Links'). Tier-1 share is the disclosed planning allocation, not purchase data. Hypotheses (Solace, Alder Bauxite) are not mapped.

Sheet Shared Dependencies
A1: ID | B1: Priority (analyst view) | C1: Shared node | D1: Why it is a hidden concentration | E1: Components affected | F1: Products affected / exposure | G1: Evidence IDs | H1: Key quote | I1: Status
A2: S1 | B2: Critical | C2: IonPeak Semiconductor Ltd. (ORG-439), SITE-074, Z01 (East Delta) | D2: Single qualified source of power semiconductor dies behind BOTH Tier-1 power-assembly suppliers. The apparent M10/M20 dual-sourcing (Aster 60/40 Boreal for M10; 70/30 for M20) collapses to one die source. | E2: M10 (P1, P3) and M20 (P2): all three products | F2: All 3 products. Combined annual product revenue exposed: USD 1,560m (P1 624, P2 520, P3 416). This is revenue of the dependent products, not supplier spend. | G2: DOC-021, DOC-023, DOC-056, DOC-077, DOC-078, SHP-00125 | H2: "The current M10/M20 programs at both Aster and Boreal use the same qualified IonPeak production die family from SITE-074. No second die source is currently qualified for these programs." (DOC-078) | I2: Confirmed
A3: S2 | B3: Critical | C3: CommonSpan Holdings Ltd. (ORG-268) - common parent of Aster and Boreal | D3: The two 'competing' Tier-1 power-assembly suppliers are ultimately owned by the same parent, and also share the same three Tier-2 suppliers (IonPeak, Lumen Magnetics, Orion Ceramics). Tier-1 diversification here is in brand only. | E3: M10, M20 | F3: All 3 products (same as S1) | G3: DOC-075, DOC-021, DOC-023, DOC-035, DOC-037, DOC-043, DOC-045 | H3: "CommonSpan Holdings Ltd. (ORG-268) consolidates Aster Power Assemblies Ltd. and Boreal Power Systems Ltd. as controlled subsidiaries. Separate brands do not imply separate ultimate ownership." (DOC-075) | I3: Confirmed (ownership statement)
A4: S3 | B4: High | C4: Jade Printed Circuits Ltd. (ORG-453), SITE-081, Z01 | D4: Sole currently-qualified substrate source for Cobalt's C10 control board AND for both B10 suppliers (Grove, HarborSense). Cobalt is itself 100% of C10, so C10 is single-chain end to end; the two B10 suppliers also share this one substrate source. | E4: C10 (P1, P2, P3) and B10 (P3) | F4: All 3 products via C10; P3 additionally via B10 | G4: DOC-025, DOC-027, DOC-029, DOC-079, DOC-076, DOC-060, DOC-064 | H4: "There is no presently qualified independent substrate in the supplied corpus" (DOC-079) | I4: Confirmed
A5: S4 | B5: High | C5: Z01 (East Delta) as a geography | D5: Five nodes on the network sit in Z01: IonPeak (Tier-2), Jade Printed Circuits (Tier-2), Orion Ceramics (Tier-2), Umber Silicon Carbide (Tier-3) and, as an inferred link, Verdant Process Gases (Tier-3). One regional event could hit power dies, circuit substrates and ceramic substrates at the same time. See 'Zone Concentration'. | E5: M10, M20, C10, B10 | F5: All 3 products | G5: DOC-021, DOC-023, DOC-025, DOC-043, DOC-045, DOC-056, DOC-058, DOC-077 | H5: "IonPeak Semiconductor Ltd. manufactures the NovaDrive-relevant production power dies at SITE-074 in East Delta (Z01)." (DOC-077) | I5: Confirmed (Verdant = Inferred)
A6: S5 | B6: Medium | C6: Kestrel Microdevices Ltd. (ORG-728), SITE-088, Z05 | D6: Microcontroller supplier to both Cobalt (C10) and Grove (B10, 80% of B10). P3 depends on Kestrel through two different components. No Kestrel link to HarborSense appears in the data (NOT IN DATA, not evidence of absence). | E6: C10 (P1, P2, P3), B10 (P3) | F6: All 3 products via C10; P3 also via B10 | G6: DOC-031, DOC-033 | H6: "The supplied input is microcontrollers, manufactured at SITE-088." (DOC-031, DOC-033) | I6: Confirmed
A7: S6 | B7: Medium | C7: Single-supplier Tier-1 components | D7: Four components have one disclosed Tier-1 supplier at ~100% of requirement: C10 (Cobalt), C20 (Delta Capacitor Works), H10 (ForgeLine), H20 (Estuary). No second Tier-1 is evidenced in the data. | E7: C10, C20, H10, H20 | F7: C10: all 3; C20: P1, P2; H10: P1; H20: P2, P3 | G7: DOC-009, DOC-011, DOC-013, DOC-015 | H7: "The disclosed contracted allocation is approximately 100% of NovaDrive requirements for this component; this is a planning allocation, not a purchase ledger" (e.g. DOC-009) | I7: Confirmed (planning allocation, not spend)
A9: Copied from the tiering workbook. These feed dimension D3 (network dependence).

Sheet Calc
A1: Entity ID | B1: Legal name | C1: Tier | D1: Link status | E1: Facility zone | F1: Indicator row | G1: Current ratio | H1: Net debt/EBITDA | I1: On-time % (3M) | J1: On-time change (pts) | K1: Assurance gap | L1: Physical hazard | M1: Logistics friction | N1: Infrastructure | O1: Reaches P1 | P1: Reaches P2 | Q1: Reaches P3 | R1: Component supply routed via it (%) | S1: Weeks to replace | T1: Tier-1s hit together | U1: Single-source level (0/50/100) | V1: Independent source families | W1: EV-001 hit (zone Z01) | X1: EV-003 hit (Meridian) | Y1: Revenue at risk (USD m) | Z1: Revenue at risk (%) | AA1: Current ratio score | AB1: Debt score | AC1: On-time score | AD1: Trend score | AE1: Indicator fields missing (of 8) | AF1: Link-evidence level (info only, not scored) | AG1: Assurance score (missing = 100) | AH1: D1 Financial & operational | AI1: D2 Location & systemic | AJ1: D3 Network dependence | AK1: D4 Criticality & substitutability | AL1: D5 External threats | AM1: D6 Information gap | AN1: OVERALL RISK % (active) | AO1: Overall % Test A | AP1: Overall % Test B | AQ1: Band | AR1: Evidence confidence | AS1: Data completeness | AT1: Confidence | AU1: Next step | AV1: Rank (active) | AW1: Rank Test A | AX1: Rank Test B
A2: ORG-453 | B2: Jade Printed Circuits Ltd. | C2: Tier-2 | D2: Confirmed | E2: Z01 | F2: =MATCH(A2,Indicators!$A$2:$A$31,0) -> 15 | G2: =IF(INDEX(Indicators!$C$2:$C$31,$F2)="","",INDEX(Indicators!$C$2:$C$31,$F2)) -> 1.55 | H2: =IF(INDEX(Indicators!$D$2:$D$31,$F2)="","",INDEX(Indicators!$D$2:$D$31,$F2)) -> 3.1 | I2: =IF(INDEX(Indicators!$E$2:$E$31,$F2)="","",INDEX(Indicators!$E$2:$E$31,$F2)) -> 86.6 | J2: =IF(INDEX(Indicators!$F$2:$F$31,$F2)="","",INDEX(Indicators!$F$2:$F$31,$F2)) -> -6.4 | K2: =IF(INDEX(Indicators!$G$2:$G$31,$F2)="","",INDEX(Indicators!$G$2:$G$31,$F2)) -> 45 | L2: =IF(INDEX(Indicators!$H$2:$H$31,$F2)="","",INDEX(Indicators!$H$2:$H$31,$F2)) -> 82 | M2: =IF(INDEX(Indicators!$I$2:$I$31,$F2)="","",INDEX(Indicators!$I$2:$I$31,$F2)) -> 76 | N2: =IF(INDEX(Indicators!$J$2:$J$31,$F2)="","",INDEX(Indicators!$J$2:$J$31,$F2)) -> 71 | O2: 1 | P2: 1 | Q2: 1 | R2: 100 | S2: 12 | T2: 3 | U2: 100 | V2: 2 | W2: =IF(E2="Z01",1,0) -> 1 | X2: 0 | Y2: =O2*Scales!$B$21+P2*Scales!$B$22+Q2*Scales!$B$23 -> 1560 | Z2: =Y2/Scales!$B$24*100 -> 100 | AA2: =IF(G2="","",(Scales!$C$4-G2)/(Scales!$C$4-Scales!$B$4)*100) -> 51.308901 | AB2: =IF(H2="","",(H2-Scales!$B$5)/(Scales!$C$5-Scales!$B$5)*100) -> 33.870968 | AC2: =(Scales!$C$6-I2)/(Scales!$C$6-Scales!$B$6)*100 -> 33.333333 | AD2: =(Scales!$C$7-J2)/(Scales!$C$7-Scales!$B$7)*100 -> 45.098039 | AE2: =8-COUNT(G2:N2) -> 0 | AF2: =IF(D2="Inferred",100,IF(V2>=2,0,50)) -> 0 | AG2: =IF(K2="",100,K2) -> 45 | AH2: =IF(AA2="",AVERAGE(AC2,AD2),AVERAGE(AA2,AB2,AC2,AD2)) -> 40.90281 | AI2: =AVERAGE(L2,M2,N2) -> 76.333333 | AJ2: =AVERAGE((T2-1)/(Scales!$B$36-1)*100,R2,U2) -> 100 | AK2: =AVERAGE(Z2,S2/Scales!$B$34*100) -> 87.5 | AL2: =MAX(W2*Scales!$B$16,X2*Scales!$B$17) -> 40 | AM2: =AVERAGE(AG2,AE2/8*100) -> 22.5 | AN2: =SUMPRODUCT(AH2:AM2,Scales!$B$11:$G$11)/Scales!$H$11 -> 69.005562 | AO2: =SUMPRODUCT(AH2:AM2,Scales!$B$12:$G$12)/Scales!$H$12 -> 61.206024 | AP2: =SUMPRODUCT(AH2:AM2,Scales!$B$13:$G$13)/Scales!$H$13 -> 58.66251 | AQ2: =IF(AN2>=Scales!$B$38,"High",IF(AN2>=Scales!$B$37,"Medium","Low")) -> High | AR2: =IF(D2<>"Confirmed","Low",IF(V2>=2,"High","Medium")) -> High | AS2: =IF(AE2=0,"High","Low") -> High | AT2: =IF(OR(AR2="Low",AS2="Low"),"Low",IF(OR(AR2="Medium",AS2="Medium"),"Medium","High")) -> High | AU2: =IF(D2="Inferred","Verify the link first (needs direct disclosure)",IF(AQ2="High",IF(AT2="Low","Verify data first","Search alternates now"),IF(AQ2="Medium","Prepare shortlist and monitor","Monitor"))) -> Search alternates now | AV2: =RANK(AN2,$AN$2:$AN$25) -> 1 | AW2: =RANK(AO2,$AO$2:$AO$25) -> 3 | AX2: =RANK(AP2,$AP$2:$AP$25) -> 4
A3: ORG-455 | B3: Umber Silicon Carbide Ltd. | C3: Tier-3 | D3: Confirmed | E3: Z01 | F3: =MATCH(A3,Indicators!$A$2:$A$31,0) -> 25 | G3: =IF(INDEX(Indicators!$C$2:$C$31,$F3)="","",INDEX(Indicators!$C$2:$C$31,$F3)) | H3: =IF(INDEX(Indicators!$D$2:$D$31,$F3)="","",INDEX(Indicators!$D$2:$D$31,$F3)) | I3: =IF(INDEX(Indicators!$E$2:$E$31,$F3)="","",INDEX(Indicators!$E$2:$E$31,$F3)) -> 80.5 | J3: =IF(INDEX(Indicators!$F$2:$F$31,$F3)="","",INDEX(Indicators!$F$2:$F$31,$F3)) -> -2.2 | K3: =IF(INDEX(Indicators!$G$2:$G$31,$F3)="","",INDEX(Indicators!$G$2:$G$31,$F3)) | L3: =IF(INDEX(Indicators!$H$2:$H$31,$F3)="","",INDEX(Indicators!$H$2:$H$31,$F3)) -> 82 | M3: =IF(INDEX(Indicators!$I$2:$I$31,$F3)="","",INDEX(Indicators!$I$2:$I$31,$F3)) -> 76 | N3: =IF(INDEX(Indicators!$J$2:$J$31,$F3)="","",INDEX(Indicators!$J$2:$J$31,$F3)) -> 71 | O3: 1 | P3: 1 | Q3: 1 | R3: 100 | S3: 16 | T3: 2 | U3: 50 | V3: 1 | W3: =IF(E3="Z01",1,0) -> 1 | X3: 0 | Y3: =O3*Scales!$B$21+P3*Scales!$B$22+Q3*Scales!$B$23 -> 1560 | Z3: =Y3/Scales!$B$24*100 -> 100 | AA3: =IF(G3="","",(Scales!$C$4-G3)/(Scales!$C$4-Scales!$B$4)*100) | AB3: =IF(H3="","",(H3-Scales!$B$5)/(Scales!$C$5-Scales!$B$5)*100) | AC3: =(Scales!$C$6-I3)/(Scales!$C$6-Scales!$B$6)*100 -> 73.202614 | AD3: =(Scales!$C$7-J3)/(Scales!$C$7-Scales!$B$7)*100 -> 24.509804 | AE3: =8-COUNT(G3:N3) -> 3 | AF3: =IF(D3="Inferred",100,IF(V3>=2,0,50)) -> 50 | AG3: =IF(K3="",100,K3) -> 100 | AH3: =IF(AA3="",AVERAGE(AC3,AD3),AVERAGE(AA3,AB3,AC3,AD3)) -> 48.856209 | AI3: =AVERAGE(L3,M3,N3) -> 76.333333 | AJ3: =AVERAGE((T3-1)/(Scales!$B$36-1)*100,R3,U3) -> 66.666667 | AK3: =AVERAGE(Z3,S3/Scales!$B$34*100) -> 100 | AL3: =MAX(W3*Scales!$B$16,X3*Scales!$B$17) -> 40 | AM3: =AVERAGE(AG3,AE3/8*100) -> 68.75 | AN3: =SUMPRODUCT(AH3:AM3,Scales!$B$11:$G$11)/Scales!$H$11 -> 67.096242 | AO3: =SUMPRODUCT(AH3:AM3,Scales!$B$12:$G$12)/Scales!$H$12 -> 66.767702 | AP3: =SUMPRODUCT(AH3:AM3,Scales!$B$13:$G$13)/Scales!$H$13 -> 64.236029 | AQ3: =IF(AN3>=Scales!$B$38,"High",IF(AN3>=Scales!$B$37,"Medium","Low")) -> High | AR3: =IF(D3<>"Confirmed","Low",IF(V3>=2,"High","Medium")) -> Medium | AS3: =IF(AE3=0,"High","Low") -> Low | AT3: =IF(OR(AR3="Low",AS3="Low"),"Low",IF(OR(AR3="Medium",AS3="Medium"),"Medium","High")) -> Low | AU3: =IF(D3="Inferred","Verify the link first (needs direct disclosure)",IF(AQ3="High",IF(AT3="Low","Verify data first","Search alternates now"),IF(AQ3="Medium","Prepare shortlist and monitor","Monitor"))) -> Verify data first | AV3: =RANK(AN3,$AN$2:$AN$25) -> 2 | AW3: =RANK(AO3,$AO$2:$AO$25) -> 1 | AX3: =RANK(AP3,$AP$2:$AP$25) -> 1
A4: ORG-736 | B4: Verdant Process Gases Ltd. | C4: Tier-3 | D4: Inferred | E4: Z01 | F4: =MATCH(A4,Indicators!$A$2:$A$31,0) -> 26 | G4: =IF(INDEX(Indicators!$C$2:$C$31,$F4)="","",INDEX(Indicators!$C$2:$C$31,$F4)) | H4: =IF(INDEX(Indicators!$D$2:$D$31,$F4)="","",INDEX(Indicators!$D$2:$D$31,$F4)) | I4: =IF(INDEX(Indicators!$E$2:$E$31,$F4)="","",INDEX(Indicators!$E$2:$E$31,$F4)) -> 81.9 | J4: =IF(INDEX(Indicators!$F$2:$F$31,$F4)="","",INDEX(Indicators!$F$2:$F$31,$F4)) -> -0.9 | K4: =IF(INDEX(Indicators!$G$2:$G$31,$F4)="","",INDEX(Indicators!$G$2:$G$31,$F4)) | L4: =IF(INDEX(Indicators!$H$2:$H$31,$F4)="","",INDEX(Indicators!$H$2:$H$31,$F4)) -> 82 | M4: =IF(INDEX(Indicators!$I$2:$I$31,$F4)="","",INDEX(Indicators!$I$2:$I$31,$F4)) -> 76 | N4: =IF(INDEX(Indicators!$J$2:$J$31,$F4)="","",INDEX(Indicators!$J$2:$J$31,$F4)) -> 71 | O4: 1 | P4: 1 | Q4: 1 | R4: 100 | S4: 16 | T4: 2 | U4: 50 | V4: 1 | W4: =IF(E4="Z01",1,0) -> 1 | X4: 0 | Y4: =O4*Scales!$B$21+P4*Scales!$B$22+Q4*Scales!$B$23 -> 1560 | Z4: =Y4/Scales!$B$24*100 -> 100 | AA4: =IF(G4="","",(Scales!$C$4-G4)/(Scales!$C$4-Scales!$B$4)*100) | AB4: =IF(H4="","",(H4-Scales!$B$5)/(Scales!$C$5-Scales!$B$5)*100) | AC4: =(Scales!$C$6-I4)/(Scales!$C$6-Scales!$B$6)*100 -> 64.052288 | AD4: =(Scales!$C$7-J4)/(Scales!$C$7-Scales!$B$7)*100 -> 18.137255 | AE4: =8-COUNT(G4:N4) -> 3 | AF4: =IF(D4="Inferred",100,IF(V4>=2,0,50)) -> 100 | AG4: =IF(K4="",100,K4) -> 100 | AH4: =IF(AA4="",AVERAGE(AC4,AD4),AVERAGE(AA4,AB4,AC4,AD4)) -> 41.094771 | AI4: =AVERAGE(L4,M4,N4) -> 76.333333 | AJ4: =AVERAGE((T4-1)/(Scales!$B$36-1)*100,R4,U4) -> 66.666667 | AK4: =AVERAGE(Z4,S4/Scales!$B$34*100) -> 100 | AL4: =MAX(W4*Scales!$B$16,X4*Scales!$B$17) -> 40 | AM4: =AVERAGE(AG4,AE4/8*100) -> 68.75 | AN4: =SUMPRODUCT(AH4:AM4,Scales!$B$11:$G$11)/Scales!$H$11 -> 65.543954 | AO4: =SUMPRODUCT(AH4:AM4,Scales!$B$12:$G$12)/Scales!$H$12 -> 65.474129 | AP4: =SUMPRODUCT(AH4:AM4,Scales!$B$13:$G$13)/Scales!$H$13 -> 61.907598 | AQ4: =IF(AN4>=Scales!$B$38,"High",IF(AN4>=Scales!$B$37,"Medium","Low")) -> High | AR4: =IF(D4<>"Confirmed","Low",IF(V4>=2,"High","Medium")) -> Low | AS4: =IF(AE4=0,"High","Low") -> Low | AT4: =IF(OR(AR4="Low",AS4="Low"),"Low",IF(OR(AR4="Medium",AS4="Medium"),"Medium","High")) -> Low | AU4: =IF(D4="Inferred","Verify the link first (needs direct disclosure)",IF(AQ4="High",IF(AT4="Low","Verify data first","Search alternates now"),IF(AQ4="Medium","Prepare shortlist and monitor","Monitor"))) -> Verify the link first (needs direct disclosure) | AV4: =RANK(AN4,$AN$2:$AN$25) -> 3 | AW4: =RANK(AO4,$AO$2:$AO$25) -> 2 | AX4: =RANK(AP4,$AP$2:$AP$25) -> 2
A5: ORG-439 | B5: IonPeak Semiconductor Ltd. | C5: Tier-2 | D5: Confirmed | E5: Z01 | F5: =MATCH(A5,Indicators!$A$2:$A$31,0) -> 13 | G5: =IF(INDEX(Indicators!$C$2:$C$31,$F5)="","",INDEX(Indicators!$C$2:$C$31,$F5)) -> 1.8 | H5: =IF(INDEX(Indicators!$D$2:$D$31,$F5)="","",INDEX(Indicators!$D$2:$D$31,$F5)) -> 2.4 | I5: =IF(INDEX(Indicators!$E$2:$E$31,$F5)="","",INDEX(Indicators!$E$2:$E$31,$F5)) -> 85.2 | J5: =IF(INDEX(Indicators!$F$2:$F$31,$F5)="","",INDEX(Indicators!$F$2:$F$31,$F5)) -> -8.8 | K5: =IF(INDEX(Indicators!$G$2:$G$31,$F5)="","",INDEX(Indicators!$G$2:$G$31,$F5)) -> 36 | L5: =IF(INDEX(Indicators!$H$2:$H$31,$F5)="","",INDEX(Indicators!$H$2:$H$31,$F5)) -> 82 | M5: =IF(INDEX(Indicators!$I$2:$I$31,$F5)="","",INDEX(Indicators!$I$2:$I$31,$F5)) -> 76 | N5: =IF(INDEX(Indicators!$J$2:$J$31,$F5)="","",INDEX(Indicators!$J$2:$J$31,$F5)) -> 71 | O5: 1 | P5: 1 | Q5: 1 | R5: 100 | S5: 16 | T5: 2 | U5: 100 | V5: 2 | W5: =IF(E5="Z01",1,0) -> 1 | X5: 0 | Y5: =O5*Scales!$B$21+P5*Scales!$B$22+Q5*Scales!$B$23 -> 1560 | Z5: =Y5/Scales!$B$24*100 -> 100 | AA5: =IF(G5="","",(Scales!$C$4-G5)/(Scales!$C$4-Scales!$B$4)*100) -> 38.219895 | AB5: =IF(H5="","",(H5-Scales!$B$5)/(Scales!$C$5-Scales!$B$5)*100) -> 22.580645 | AC5: =(Scales!$C$6-I5)/(Scales!$C$6-Scales!$B$6)*100 -> 42.48366 | AD5: =(Scales!$C$7-J5)/(Scales!$C$7-Scales!$B$7)*100 -> 56.862745 | AE5: =8-COUNT(G5:N5) -> 0 | AF5: =IF(D5="Inferred",100,IF(V5>=2,0,50)) -> 0 | AG5: =IF(K5="",100,K5) -> 36 | AH5: =IF(AA5="",AVERAGE(AC5,AD5),AVERAGE(AA5,AB5,AC5,AD5)) -> 40.036736 | AI5: =AVERAGE(L5,M5,N5) -> 76.333333 | AJ5: =AVERAGE((T5-1)/(Scales!$B$36-1)*100,R5,U5) -> 83.333333 | AK5: =AVERAGE(Z5,S5/Scales!$B$34*100) -> 100 | AL5: =MAX(W5*Scales!$B$16,X5*Scales!$B$17) -> 40 | AM5: =AVERAGE(AG5,AE5/8*100) -> 18 | AN5: =SUMPRODUCT(AH5:AM5,Scales!$B$11:$G$11)/Scales!$H$11 -> 65.257347 | AO5: =SUMPRODUCT(AH5:AM5,Scales!$B$12:$G$12)/Scales!$H$12 -> 59.617234 | AP5: =SUMPRODUCT(AH5:AM5,Scales!$B$13:$G$13)/Scales!$H$13 -> 56.477688 | AQ5: =IF(AN5>=Scales!$B$38,"High",IF(AN5>=Scales!$B$37,"Medium","Low")) -> High | AR5: =IF(D5<>"Confirmed","Low",IF(V5>=2,"High","Medium")) -> High | AS5: =IF(AE5=0,"High","Low") -> High | AT5: =IF(OR(AR5="Low",AS5="Low"),"Low",IF(OR(AR5="Medium",AS5="Medium"),"Medium","High")) -> High | AU5: =IF(D5="Inferred","Verify the link first (needs direct disclosure)",IF(AQ5="High",IF(AT5="Low","Verify data first","Search alternates now"),IF(AQ5="Medium","Prepare shortlist and monitor","Monitor"))) -> Search alternates now | AV5: =RANK(AN5,$AN$2:$AN$25) -> 4 | AW5: =RANK(AO5,$AO$2:$AO$25) -> 4 | AX5: =RANK(AP5,$AP$2:$AP$25) -> 5
A6: ORG-708 | B6: Orion Ceramics Ltd. | C6: Tier-2 | D6: Confirmed | E6: Z01 | F6: =MATCH(A6,Indicators!$A$2:$A$31,0) -> 20 | G6: =IF(INDEX(Indicators!$C$2:$C$31,$F6)="","",INDEX(Indicators!$C$2:$C$31,$F6)) -> 2.29 | H6: =IF(INDEX(Indicators!$D$2:$D$31,$F6)="","",INDEX(Indicators!$D$2:$D$31,$F6)) -> 2.67 | I6: =IF(INDEX(Indicators!$E$2:$E$31,$F6)="","",INDEX(Indicators!$E$2:$E$31,$F6)) -> 82.2 | J6: =IF(INDEX(Indicators!$F$2:$F$31,$F6)="","",INDEX(Indicators!$F$2:$F$31,$F6)) -> 0.7 | K6: =IF(INDEX(Indicators!$G$2:$G$31,$F6)="","",INDEX(Indicators!$G$2:$G$31,$F6)) -> 30 | L6: =IF(INDEX(Indicators!$H$2:$H$31,$F6)="","",INDEX(Indicators!$H$2:$H$31,$F6)) -> 82 | M6: =IF(INDEX(Indicators!$I$2:$I$31,$F6)="","",INDEX(Indicators!$I$2:$I$31,$F6)) -> 76 | N6: =IF(INDEX(Indicators!$J$2:$J$31,$F6)="","",INDEX(Indicators!$J$2:$J$31,$F6)) -> 71 | O6: 1 | P6: 1 | Q6: 1 | R6: 100 | S6: 16 | T6: 2 | U6: 50 | V6: 1 | W6: =IF(E6="Z01",1,0) -> 1 | X6: 0 | Y6: =O6*Scales!$B$21+P6*Scales!$B$22+Q6*Scales!$B$23 -> 1560 | Z6: =Y6/Scales!$B$24*100 -> 100 | AA6: =IF(G6="","",(Scales!$C$4-G6)/(Scales!$C$4-Scales!$B$4)*100) -> 12.565445 | AB6: =IF(H6="","",(H6-Scales!$B$5)/(Scales!$C$5-Scales!$B$5)*100) -> 26.935484 | AC6: =(Scales!$C$6-I6)/(Scales!$C$6-Scales!$B$6)*100 -> 62.091503 | AD6: =(Scales!$C$7-J6)/(Scales!$C$7-Scales!$B$7)*100 -> 10.294118 | AE6: =8-COUNT(G6:N6) -> 0 | AF6: =IF(D6="Inferred",100,IF(V6>=2,0,50)) -> 50 | AG6: =IF(K6="",100,K6) -> 30 | AH6: =IF(AA6="",AVERAGE(AC6,AD6),AVERAGE(AA6,AB6,AC6,AD6)) -> 27.971637 | AI6: =AVERAGE(L6,M6,N6) -> 76.333333 | AJ6: =AVERAGE((T6-1)/(Scales!$B$36-1)*100,R6,U6) -> 66.666667 | AK6: =AVERAGE(Z6,S6/Scales!$B$34*100) -> 100 | AL6: =MAX(W6*Scales!$B$16,X6*Scales!$B$17) -> 40 | AM6: =AVERAGE(AG6,AE6/8*100) -> 15 | AN6: =SUMPRODUCT(AH6:AM6,Scales!$B$11:$G$11)/Scales!$H$11 -> 57.544327 | AO6: =SUMPRODUCT(AH6:AM6,Scales!$B$12:$G$12)/Scales!$H$12 -> 54.328606 | AP6: =SUMPRODUCT(AH6:AM6,Scales!$B$13:$G$13)/Scales!$H$13 -> 49.908158 | AQ6: =IF(AN6>=Scales!$B$38,"High",IF(AN6>=Scales!$B$37,"Medium","Low")) -> High | AR6: =IF(D6<>"Confirmed","Low",IF(V6>=2,"High","Medium")) -> Medium | AS6: =IF(AE6=0,"High","Low") -> High | AT6: =IF(OR(AR6="Low",AS6="Low"),"Low",IF(OR(AR6="Medium",AS6="Medium"),"Medium","High")) -> Medium | AU6: =IF(D6="Inferred","Verify the link first (needs direct disclosure)",IF(AQ6="High",IF(AT6="Low","Verify data first","Search alternates now"),IF(AQ6="Medium","Prepare shortlist and monitor","Monitor"))) -> Search alternates now | AV6: =RANK(AN6,$AN$2:$AN$25) -> 5 | AW6: =RANK(AO6,$AO$2:$AO$25) -> 6 | AX6: =RANK(AP6,$AP$2:$AP$25) -> 6
A7: ORG-210 | B7: Meridian Dielectrics Ltd. | C7: Tier-2 | D7: Confirmed | E7: Z03 | F7: =MATCH(A7,Indicators!$A$2:$A$31,0) -> 18 | G7: =IF(INDEX(Indicators!$C$2:$C$31,$F7)="","",INDEX(Indicators!$C$2:$C$31,$F7)) -> 0.62 | H7: =IF(INDEX(Indicators!$D$2:$D$31,$F7)="","",INDEX(Indicators!$D$2:$D$31,$F7)) -> 7.2 | I7: =IF(INDEX(Indicators!$E$2:$E$31,$F7)="","",INDEX(Indicators!$E$2:$E$31,$F7)) -> 76.4 | J7: =IF(INDEX(Indicators!$F$2:$F$31,$F7)="","",INDEX(Indicators!$F$2:$F$31,$F7)) -> -17.6 | K7: =IF(INDEX(Indicators!$G$2:$G$31,$F7)="","",INDEX(Indicators!$G$2:$G$31,$F7)) -> 72 | L7: =IF(INDEX(Indicators!$H$2:$H$31,$F7)="","",INDEX(Indicators!$H$2:$H$31,$F7)) -> 19 | M7: =IF(INDEX(Indicators!$I$2:$I$31,$F7)="","",INDEX(Indicators!$I$2:$I$31,$F7)) -> 26 | N7: =IF(INDEX(Indicators!$J$2:$J$31,$F7)="","",INDEX(Indicators!$J$2:$J$31,$F7)) -> 25 | O7: 1 | P7: 1 | Q7: 0 | R7: 100 | S7: 8 | T7: 1 | U7: 50 | V7: 1 | W7: =IF(E7="Z01",1,0) -> 0 | X7: 1 | Y7: =O7*Scales!$B$21+P7*Scales!$B$22+Q7*Scales!$B$23 -> 1144 | Z7: =Y7/Scales!$B$24*100 -> 73.333333 | AA7: =IF(G7="","",(Scales!$C$4-G7)/(Scales!$C$4-Scales!$B$4)*100) -> 100 | AB7: =IF(H7="","",(H7-Scales!$B$5)/(Scales!$C$5-Scales!$B$5)*100) -> 100 | AC7: =(Scales!$C$6-I7)/(Scales!$C$6-Scales!$B$6)*100 -> 100 | AD7: =(Scales!$C$7-J7)/(Scales!$C$7-Scales!$B$7)*100 -> 100 | AE7: =8-COUNT(G7:N7) -> 0 | AF7: =IF(D7="Inferred",100,IF(V7>=2,0,50)) -> 50 | AG7: =IF(K7="",100,K7) -> 72 | AH7: =IF(AA7="",AVERAGE(AC7,AD7),AVERAGE(AA7,AB7,AC7,AD7)) -> 100 | AI7: =AVERAGE(L7,M7,N7) -> 23.333333 | AJ7: =AVERAGE((T7-1)/(Scales!$B$36-1)*100,R7,U7) -> 50 | AK7: =AVERAGE(Z7,S7/Scales!$B$34*100) -> 61.666667 | AL7: =MAX(W7*Scales!$B$16,X7*Scales!$B$17) -> 60 | AM7: =AVERAGE(AG7,AE7/8*100) -> 36 | AN7: =SUMPRODUCT(AH7:AM7,Scales!$B$11:$G$11)/Scales!$H$11 -> 57.35 | AO7: =SUMPRODUCT(AH7:AM7,Scales!$B$12:$G$12)/Scales!$H$12 -> 55.166667 | AP7: =SUMPRODUCT(AH7:AM7,Scales!$B$13:$G$13)/Scales!$H$13 -> 59.733333 | AQ7: =IF(AN7>=Scales!$B$38,"High",IF(AN7>=Scales!$B$37,"Medium","Low")) -> High | AR7: =IF(D7<>"Confirmed","Low",IF(V7>=2,"High","Medium")) -> Medium | AS7: =IF(AE7=0,"High","Low") -> High | AT7: =IF(OR(AR7="Low",AS7="Low"),"Low",IF(OR(AR7="Medium",AS7="Medium"),"Medium","High")) -> Medium | AU7: =IF(D7="Inferred","Verify the link first (needs direct disclosure)",IF(AQ7="High",IF(AT7="Low","Verify data first","Search alternates now"),IF(AQ7="Medium","Prepare shortlist and monitor","Monitor"))) -> Search alternates now | AV7: =RANK(AN7,$AN$2:$AN$25) -> 6 | AW7: =RANK(AO7,$AO$2:$AO$25) -> 5 | AX7: =RANK(AP7,$AP$2:$AP$25) -> 3
A8: ORG-873 | B8: Warden Copper Foil Ltd. | C8: Tier-3 | D8: Confirmed | E8: Z06 | F8: =MATCH(A8,Indicators!$A$2:$A$31,0) -> 27 | G8: =IF(INDEX(Indicators!$C$2:$C$31,$F8)="","",INDEX(Indicators!$C$2:$C$31,$F8)) | H8: =IF(INDEX(Indicators!$D$2:$D$31,$F8)="","",INDEX(Indicators!$D$2:$D$31,$F8)) | I8: =IF(INDEX(Indicators!$E$2:$E$31,$F8)="","",INDEX(Indicators!$E$2:$E$31,$F8)) -> 87.4 | J8: =IF(INDEX(Indicators!$F$2:$F$31,$F8)="","",INDEX(Indicators!$F$2:$F$31,$F8)) -> 1.8 | K8: =IF(INDEX(Indicators!$G$2:$G$31,$F8)="","",INDEX(Indicators!$G$2:$G$31,$F8)) | L8: =IF(INDEX(Indicators!$H$2:$H$31,$F8)="","",INDEX(Indicators!$H$2:$H$31,$F8)) -> 67 | M8: =IF(INDEX(Indicators!$I$2:$I$31,$F8)="","",INDEX(Indicators!$I$2:$I$31,$F8)) -> 59 | N8: =IF(INDEX(Indicators!$J$2:$J$31,$F8)="","",INDEX(Indicators!$J$2:$J$31,$F8)) -> 54 | O8: 1 | P8: 1 | Q8: 1 | R8: 100 | S8: 12 | T8: 3 | U8: 50 | V8: 1 | W8: =IF(E8="Z01",1,0) -> 0 | X8: 0 | Y8: =O8*Scales!$B$21+P8*Scales!$B$22+Q8*Scales!$B$23 -> 1560 | Z8: =Y8/Scales!$B$24*100 -> 100 | AA8: =IF(G8="","",(Scales!$C$4-G8)/(Scales!$C$4-Scales!$B$4)*100) | AB8: =IF(H8="","",(H8-Scales!$B$5)/(Scales!$C$5-Scales!$B$5)*100) | AC8: =(Scales!$C$6-I8)/(Scales!$C$6-Scales!$B$6)*100 -> 28.104575 | AD8: =(Scales!$C$7-J8)/(Scales!$C$7-Scales!$B$7)*100 -> 4.9019608 | AE8: =8-COUNT(G8:N8) -> 3 | AF8: =IF(D8="Inferred",100,IF(V8>=2,0,50)) -> 50 | AG8: =IF(K8="",100,K8) -> 100 | AH8: =IF(AA8="",AVERAGE(AC8,AD8),AVERAGE(AA8,AB8,AC8,AD8)) -> 16.503268 | AI8: =AVERAGE(L8,M8,N8) -> 60 | AJ8: =AVERAGE((T8-1)/(Scales!$B$36-1)*100,R8,U8) -> 83.333333 | AK8: =AVERAGE(Z8,S8/Scales!$B$34*100) -> 87.5 | AL8: =MAX(W8*Scales!$B$16,X8*Scales!$B$17) -> 0 | AM8: =AVERAGE(AG8,AE8/8*100) -> 68.75 | AN8: =SUMPRODUCT(AH8:AM8,Scales!$B$11:$G$11)/Scales!$H$11 -> 57.300654 | AO8: =SUMPRODUCT(AH8:AM8,Scales!$B$12:$G$12)/Scales!$H$12 -> 52.6811 | AP8: =SUMPRODUCT(AH8:AM8,Scales!$B$13:$G$13)/Scales!$H$13 -> 48.51348 | AQ8: =IF(AN8>=Scales!$B$38,"High",IF(AN8>=Scales!$B$37,"Medium","Low")) -> High | AR8: =IF(D8<>"Confirmed","Low",IF(V8>=2,"High","Medium")) -> Medium | AS8: =IF(AE8=0,"High","Low") -> Low | AT8: =IF(OR(AR8="Low",AS8="Low"),"Low",IF(OR(AR8="Medium",AS8="Medium"),"Medium","High")) -> Low | AU8: =IF(D8="Inferred","Verify the link first (needs direct disclosure)",IF(AQ8="High",IF(AT8="Low","Verify data first","Search alternates now"),IF(AQ8="Medium","Prepare shortlist and monitor","Monitor"))) -> Verify data first | AV8: =RANK(AN8,$AN$2:$AN$25) -> 7 | AW8: =RANK(AO8,$AO$2:$AO$25) -> 7 | AX8: =RANK(AP8,$AP$2:$AP$25) -> 7
A9: ORG-179 | B9: Xenon Resin Ltd. | C9: Tier-3 | D9: Confirmed | E9: Z04 | F9: =MATCH(A9,Indicators!$A$2:$A$31,0) -> 28 | G9: =IF(INDEX(Indicators!$C$2:$C$31,$F9)="","",INDEX(Indicators!$C$2:$C$31,$F9)) | H9: =IF(INDEX(Indicators!$D$2:$D$31,$F9)="","",INDEX(Indicators!$D$2:$D$31,$F9)) | I9: =IF(INDEX(Indicators!$E$2:$E$31,$F9)="","",INDEX(Indicators!$E$2:$E$31,$F9)) -> 87.3 | J9: =IF(INDEX(Indicators!$F$2:$F$31,$F9)="","",INDEX(Indicators!$F$2:$F$31,$F9)) -> 1.8 | K9: =IF(INDEX(Indicators!$G$2:$G$31,$F9)="","",INDEX(Indicators!$G$2:$G$31,$F9)) | L9: =IF(INDEX(Indicators!$H$2:$H$31,$F9)="","",INDEX(Indicators!$H$2:$H$31,$F9)) -> 58 | M9: =IF(INDEX(Indicators!$I$2:$I$31,$F9)="","",INDEX(Indicators!$I$2:$I$31,$F9)) -> 62 | N9: =IF(INDEX(Indicators!$J$2:$J$31,$F9)="","",INDEX(Indicators!$J$2:$J$31,$F9)) -> 52 | O9: 1 | P9: 1 | Q9: 1 | R9: 100 | S9: 12 | T9: 3 | U9: 50 | V9: 1 | W9: =IF(E9="Z01",1,0) -> 0 | X9: 0 | Y9: =O9*Scales!$B$21+P9*Scales!$B$22+Q9*Scales!$B$23 -> 1560 | Z9: =Y9/Scales!$B$24*100 -> 100 | AA9: =IF(G9="","",(Scales!$C$4-G9)/(Scales!$C$4-Scales!$B$4)*100) | AB9: =IF(H9="","",(H9-Scales!$B$5)/(Scales!$C$5-Scales!$B$5)*100) | AC9: =(Scales!$C$6-I9)/(Scales!$C$6-Scales!$B$6)*100 -> 28.75817 | AD9: =(Scales!$C$7-J9)/(Scales!$C$7-Scales!$B$7)*100 -> 4.9019608 | AE9: =8-COUNT(G9:N9) -> 3 | AF9: =IF(D9="Inferred",100,IF(V9>=2,0,50)) -> 50 | AG9: =IF(K9="",100,K9) -> 100 | AH9: =IF(AA9="",AVERAGE(AC9,AD9),AVERAGE(AA9,AB9,AC9,AD9)) -> 16.830065 | AI9: =AVERAGE(L9,M9,N9) -> 57.333333 | AJ9: =AVERAGE((T9-1)/(Scales!$B$36-1)*100,R9,U9) -> 83.333333 | AK9: =AVERAGE(Z9,S9/Scales!$B$34*100) -> 87.5 | AL9: =MAX(W9*Scales!$B$16,X9*Scales!$B$17) -> 0 | AM9: =AVERAGE(AG9,AE9/8*100) -> 68.75 | AN9: =SUMPRODUCT(AH9:AM9,Scales!$B$11:$G$11)/Scales!$H$11 -> 56.966013 | AO9: =SUMPRODUCT(AH9:AM9,Scales!$B$12:$G$12)/Scales!$H$12 -> 52.291122 | AP9: =SUMPRODUCT(AH9:AM9,Scales!$B$13:$G$13)/Scales!$H$13 -> 48.078186 | AQ9: =IF(AN9>=Scales!$B$38,"High",IF(AN9>=Scales!$B$37,"Medium","Low")) -> High | AR9: =IF(D9<>"Confirmed","Low",IF(V9>=2,"High","Medium")) -> Medium | AS9: =IF(AE9=0,"High","Low") -> Low | AT9: =IF(OR(AR9="Low",AS9="Low"),"Low",IF(OR(AR9="Medium",AS9="Medium"),"Medium","High")) -> Low | AU9: =IF(D9="Inferred","Verify the link first (needs direct disclosure)",IF(AQ9="High",IF(AT9="Low","Verify data first","Search alternates now"),IF(AQ9="Medium","Prepare shortlist and monitor","Monitor"))) -> Verify data first | AV9: =RANK(AN9,$AN$2:$AN$25) -> 8 | AW9: =RANK(AO9,$AO$2:$AO$25) -> 8 | AX9: =RANK(AP9,$AP$2:$AP$25) -> 8
A10: ORG-942 | B10: Lumen Magnetics Ltd. | C10: Tier-2 | D10: Confirmed | E10: Z04 | F10: =MATCH(A10,Indicators!$A$2:$A$31,0) -> 17 | G10: =IF(INDEX(Indicators!$C$2:$C$31,$F10)="","",INDEX(Indicators!$C$2:$C$31,$F10)) -> 1.37 | H10: =IF(INDEX(Indicators!$D$2:$D$31,$F10)="","",INDEX(Indicators!$D$2:$D$31,$F10)) -> 3 | I10: =IF(INDEX(Indicators!$E$2:$E$31,$F10)="","",INDEX(Indicators!$E$2:$E$31,$F10)) -> 89.5 | J10: =IF(INDEX(Indicators!$F$2:$F$31,$F10)="","",INDEX(Indicators!$F$2:$F$31,$F10)) -> -0.6 | K10: =IF(INDEX(Indicators!$G$2:$G$31,$F10)="","",INDEX(Indicators!$G$2:$G$31,$F10)) -> 63 | L10: =IF(INDEX(Indicators!$H$2:$H$31,$F10)="","",INDEX(Indicators!$H$2:$H$31,$F10)) -> 58 | M10: =IF(INDEX(Indicators!$I$2:$I$31,$F10)="","",INDEX(Indicators!$I$2:$I$31,$F10)) -> 62 | N10: =IF(INDEX(Indicators!$J$2:$J$31,$F10)="","",INDEX(Indicators!$J$2:$J$31,$F10)) -> 52 | O10: 1 | P10: 1 | Q10: 1 | R10: 100 | S10: 16 | T10: 2 | U10: 50 | V10: 1 | W10: =IF(E10="Z01",1,0) -> 0 | X10: 0 | Y10: =O10*Scales!$B$21+P10*Scales!$B$22+Q10*Scales!$B$23 -> 1560 | Z10: =Y10/Scales!$B$24*100 -> 100 | AA10: =IF(G10="","",(Scales!$C$4-G10)/(Scales!$C$4-Scales!$B$4)*100) -> 60.732984 | AB10: =IF(H10="","",(H10-Scales!$B$5)/(Scales!$C$5-Scales!$B$5)*100) -> 32.258065 | AC10: =(Scales!$C$6-I10)/(Scales!$C$6-Scales!$B$6)*100 -> 14.379085 | AD10: =(Scales!$C$7-J10)/(Scales!$C$7-Scales!$B$7)*100 -> 16.666667 | AE10: =8-COUNT(G10:N10) -> 0 | AF10: =IF(D10="Inferred",100,IF(V10>=2,0,50)) -> 50 | AG10: =IF(K10="",100,K10) -> 63 | AH10: =IF(AA10="",AVERAGE(AC10,AD10),AVERAGE(AA10,AB10,AC10,AD10)) -> 31.0092 | AI10: =AVERAGE(L10,M10,N10) -> 57.333333 | AJ10: =AVERAGE((T10-1)/(Scales!$B$36-1)*100,R10,U10) -> 66.666667 | AK10: =AVERAGE(Z10,S10/Scales!$B$34*100) -> 100 | AL10: =MAX(W10*Scales!$B$16,X10*Scales!$B$17) -> 0 | AM10: =AVERAGE(AG10,AE10/8*100) -> 31.5 | AN10: =SUMPRODUCT(AH10:AM10,Scales!$B$11:$G$11)/Scales!$H$11 -> 52.95184 | AO10: =SUMPRODUCT(AH10:AM10,Scales!$B$12:$G$12)/Scales!$H$12 -> 47.751533 | AP10: =SUMPRODUCT(AH10:AM10,Scales!$B$13:$G$13)/Scales!$H$13 -> 45.494427 | AQ10: =IF(AN10>=Scales!$B$38,"High",IF(AN10>=Scales!$B$37,"Medium","Low")) -> Medium | AR10: =IF(D10<>"Confirmed","Low",IF(V10>=2,"High","Medium")) -> Medium | AS10: =IF(AE10=0,"High","Low") -> High | AT10: =IF(OR(AR10="Low",AS10="Low"),"Low",IF(OR(AR10="Medium",AS10="Medium"),"Medium","High")) -> Medium | AU10: =IF(D10="Inferred","Verify the link first (needs direct disclosure)",IF(AQ10="High",IF(AT10="Low","Verify data first","Search alternates now"),IF(AQ10="Medium","Prepare shortlist and monitor","Monitor"))) -> Prepare shortlist and monitor | AV10: =RANK(AN10,$AN$2:$AN$25) -> 9 | AW10: =RANK(AO10,$AO$2:$AO$25) -> 10 | AX10: =RANK(AP10,$AP$2:$AP$25) -> 9
A11: ORG-520 | B11: Yarrow Specialty Minerals Ltd. | C11: Tier-3 | D11: Confirmed | E11: Z08 | F11: =MATCH(A11,Indicators!$A$2:$A$31,0) -> 29 | G11: =IF(INDEX(Indicators!$C$2:$C$31,$F11)="","",INDEX(Indicators!$C$2:$C$31,$F11)) | H11: =IF(INDEX(Indicators!$D$2:$D$31,$F11)="","",INDEX(Indicators!$D$2:$D$31,$F11)) | I11: =IF(INDEX(Indicators!$E$2:$E$31,$F11)="","",INDEX(Indicators!$E$2:$E$31,$F11)) -> 90.1 | J11: =IF(INDEX(Indicators!$F$2:$F$31,$F11)="","",INDEX(Indicators!$F$2:$F$31,$F11)) -> -1.2 | K11: =IF(INDEX(Indicators!$G$2:$G$31,$F11)="","",INDEX(Indicators!$G$2:$G$31,$F11)) | L11: =IF(INDEX(Indicators!$H$2:$H$31,$F11)="","",INDEX(Indicators!$H$2:$H$31,$F11)) -> 39 | M11: =IF(INDEX(Indicators!$I$2:$I$31,$F11)="","",INDEX(Indicators!$I$2:$I$31,$F11)) -> 47 | N11: =IF(INDEX(Indicators!$J$2:$J$31,$F11)="","",INDEX(Indicators!$J$2:$J$31,$F11)) -> 41 | O11: 1 | P11: 1 | Q11: 1 | R11: 100 | S11: 16 | T11: 2 | U11: 50 | V11: 1 | W11: =IF(E11="Z01",1,0) -> 0 | X11: 0 | Y11: =O11*Scales!$B$21+P11*Scales!$B$22+Q11*Scales!$B$23 -> 1560 | Z11: =Y11/Scales!$B$24*100 -> 100 | AA11: =IF(G11="","",(Scales!$C$4-G11)/(Scales!$C$4-Scales!$B$4)*100) | AB11: =IF(H11="","",(H11-Scales!$B$5)/(Scales!$C$5-Scales!$B$5)*100) | AC11: =(Scales!$C$6-I11)/(Scales!$C$6-Scales!$B$6)*100 -> 10.457516 | AD11: =(Scales!$C$7-J11)/(Scales!$C$7-Scales!$B$7)*100 -> 19.607843 | AE11: =8-COUNT(G11:N11) -> 3 | AF11: =IF(D11="Inferred",100,IF(V11>=2,0,50)) -> 50 | AG11: =IF(K11="",100,K11) -> 100 | AH11: =IF(AA11="",AVERAGE(AC11,AD11),AVERAGE(AA11,AB11,AC11,AD11)) -> 15.03268 | AI11: =AVERAGE(L11,M11,N11) -> 42.333333 | AJ11: =AVERAGE((T11-1)/(Scales!$B$36-1)*100,R11,U11) -> 66.666667 | AK11: =AVERAGE(Z11,S11/Scales!$B$34*100) -> 100 | AL11: =MAX(W11*Scales!$B$16,X11*Scales!$B$17) -> 0 | AM11: =AVERAGE(AG11,AE11/8*100) -> 68.75 | AN11: =SUMPRODUCT(AH11:AM11,Scales!$B$11:$G$11)/Scales!$H$11 -> 51.231536 | AO11: =SUMPRODUCT(AH11:AM11,Scales!$B$12:$G$12)/Scales!$H$12 -> 48.797113 | AP11: =SUMPRODUCT(AH11:AM11,Scales!$B$13:$G$13)/Scales!$H$13 -> 43.288971 | AQ11: =IF(AN11>=Scales!$B$38,"High",IF(AN11>=Scales!$B$37,"Medium","Low")) -> Medium | AR11: =IF(D11<>"Confirmed","Low",IF(V11>=2,"High","Medium")) -> Medium | AS11: =IF(AE11=0,"High","Low") -> Low | AT11: =IF(OR(AR11="Low",AS11="Low"),"Low",IF(OR(AR11="Medium",AS11="Medium"),"Medium","High")) -> Low | AU11: =IF(D11="Inferred","Verify the link first (needs direct disclosure)",IF(AQ11="High",IF(AT11="Low","Verify data first","Search alternates now"),IF(AQ11="Medium","Prepare shortlist and monitor","Monitor"))) -> Prepare shortlist and monitor | AV11: =RANK(AN11,$AN$2:$AN$25) -> 10 | AW11: =RANK(AO11,$AO$2:$AO$25) -> 9 | AX11: =RANK(AP11,$AP$2:$AP$25) -> 11
A12: ORG-119 | B12: Cobalt Control Electronics Ltd. | C12: Tier-1 | D12: Confirmed | E12: Z04 | F12: =MATCH(A12,Indicators!$A$2:$A$31,0) -> 3 | G12: =IF(INDEX(Indicators!$C$2:$C$31,$F12)="","",INDEX(Indicators!$C$2:$C$31,$F12)) -> 2.34 | H12: =IF(INDEX(Indicators!$D$2:$D$31,$F12)="","",INDEX(Indicators!$D$2:$D$31,$F12)) -> 4 | I12: =IF(INDEX(Indicators!$E$2:$E$31,$F12)="","",INDEX(Indicators!$E$2:$E$31,$F12)) -> 83.3 | J12: =IF(INDEX(Indicators!$F$2:$F$31,$F12)="","",INDEX(Indicators!$F$2:$F$31,$F12)) -> -2.3 | K12: =IF(INDEX(Indicators!$G$2:$G$31,$F12)="","",INDEX(Indicators!$G$2:$G$31,$F12)) -> 42 | L12: =IF(INDEX(Indicators!$H$2:$H$31,$F12)="","",INDEX(Indicators!$H$2:$H$31,$F12)) -> 58 | M12: =IF(INDEX(Indicators!$I$2:$I$31,$F12)="","",INDEX(Indicators!$I$2:$I$31,$F12)) -> 62 | N12: =IF(INDEX(Indicators!$J$2:$J$31,$F12)="","",INDEX(Indicators!$J$2:$J$31,$F12)) -> 52 | O12: 1 | P12: 1 | Q12: 1 | R12: 100 | S12: 12 | T12: 1 | U12: 100 | V12: 3 | W12: =IF(E12="Z01",1,0) -> 0 | X12: 0 | Y12: =O12*Scales!$B$21+P12*Scales!$B$22+Q12*Scales!$B$23 -> 1560 | Z12: =Y12/Scales!$B$24*100 -> 100 | AA12: =IF(G12="","",(Scales!$C$4-G12)/(Scales!$C$4-Scales!$B$4)*100) -> 9.947644 | AB12: =IF(H12="","",(H12-Scales!$B$5)/(Scales!$C$5-Scales!$B$5)*100) -> 48.387097 | AC12: =(Scales!$C$6-I12)/(Scales!$C$6-Scales!$B$6)*100 -> 54.901961 | AD12: =(Scales!$C$7-J12)/(Scales!$C$7-Scales!$B$7)*100 -> 25 | AE12: =8-COUNT(G12:N12) -> 0 | AF12: =IF(D12="Inferred",100,IF(V12>=2,0,50)) -> 0 | AG12: =IF(K12="",100,K12) -> 42 | AH12: =IF(AA12="",AVERAGE(AC12,AD12),AVERAGE(AA12,AB12,AC12,AD12)) -> 34.559175 | AI12: =AVERAGE(L12,M12,N12) -> 57.333333 | AJ12: =AVERAGE((T12-1)/(Scales!$B$36-1)*100,R12,U12) -> 66.666667 | AK12: =AVERAGE(Z12,S12/Scales!$B$34*100) -> 87.5 | AL12: =MAX(W12*Scales!$B$16,X12*Scales!$B$17) -> 0 | AM12: =AVERAGE(AG12,AE12/8*100) -> 21 | AN12: =SUMPRODUCT(AH12:AM12,Scales!$B$11:$G$11)/Scales!$H$11 -> 50.736835 | AO12: =SUMPRODUCT(AH12:AM12,Scales!$B$12:$G$12)/Scales!$H$12 -> 44.509863 | AP12: =SUMPRODUCT(AH12:AM12,Scales!$B$13:$G$13)/Scales!$H$13 -> 43.734419 | AQ12: =IF(AN12>=Scales!$B$38,"High",IF(AN12>=Scales!$B$37,"Medium","Low")) -> Medium | AR12: =IF(D12<>"Confirmed","Low",IF(V12>=2,"High","Medium")) -> High | AS12: =IF(AE12=0,"High","Low") -> High | AT12: =IF(OR(AR12="Low",AS12="Low"),"Low",IF(OR(AR12="Medium",AS12="Medium"),"Medium","High")) -> High | AU12: =IF(D12="Inferred","Verify the link first (needs direct disclosure)",IF(AQ12="High",IF(AT12="Low","Verify data first","Search alternates now"),IF(AQ12="Medium","Prepare shortlist and monitor","Monitor"))) -> Prepare shortlist and monitor | AV12: =RANK(AN12,$AN$2:$AN$25) -> 11 | AW12: =RANK(AO12,$AO$2:$AO$25) -> 11 | AX12: =RANK(AP12,$AP$2:$AP$25) -> 10
A13: ORG-728 | B13: Kestrel Microdevices Ltd. | C13: Tier-2 | D13: Confirmed | E13: Z05 | F13: =MATCH(A13,Indicators!$A$2:$A$31,0) -> 16 | G13: =IF(INDEX(Indicators!$C$2:$C$31,$F13)="","",INDEX(Indicators!$C$2:$C$31,$F13)) -> 1.86 | H13: =IF(INDEX(Indicators!$D$2:$D$31,$F13)="","",INDEX(Indicators!$D$2:$D$31,$F13)) -> 2 | I13: =IF(INDEX(Indicators!$E$2:$E$31,$F13)="","",INDEX(Indicators!$E$2:$E$31,$F13)) -> 87.3 | J13: =IF(INDEX(Indicators!$F$2:$F$31,$F13)="","",INDEX(Indicators!$F$2:$F$31,$F13)) -> 1.6 | K13: =IF(INDEX(Indicators!$G$2:$G$31,$F13)="","",INDEX(Indicators!$G$2:$G$31,$F13)) -> 54 | L13: =IF(INDEX(Indicators!$H$2:$H$31,$F13)="","",INDEX(Indicators!$H$2:$H$31,$F13)) -> 31 | M13: =IF(INDEX(Indicators!$I$2:$I$31,$F13)="","",INDEX(Indicators!$I$2:$I$31,$F13)) -> 23 | N13: =IF(INDEX(Indicators!$J$2:$J$31,$F13)="","",INDEX(Indicators!$J$2:$J$31,$F13)) -> 19 | O13: 1 | P13: 1 | Q13: 1 | R13: 100 | S13: 12 | T13: 2 | U13: 50 | V13: 1 | W13: =IF(E13="Z01",1,0) -> 0 | X13: 0 | Y13: =O13*Scales!$B$21+P13*Scales!$B$22+Q13*Scales!$B$23 -> 1560 | Z13: =Y13/Scales!$B$24*100 -> 100 | AA13: =IF(G13="","",(Scales!$C$4-G13)/(Scales!$C$4-Scales!$B$4)*100) -> 35.078534 | AB13: =IF(H13="","",(H13-Scales!$B$5)/(Scales!$C$5-Scales!$B$5)*100) -> 16.129032 | AC13: =(Scales!$C$6-I13)/(Scales!$C$6-Scales!$B$6)*100 -> 28.75817 | AD13: =(Scales!$C$7-J13)/(Scales!$C$7-Scales!$B$7)*100 -> 5.8823529 | AE13: =8-COUNT(G13:N13) -> 0 | AF13: =IF(D13="Inferred",100,IF(V13>=2,0,50)) -> 50 | AG13: =IF(K13="",100,K13) -> 54 | AH13: =IF(AA13="",AVERAGE(AC13,AD13),AVERAGE(AA13,AB13,AC13,AD13)) -> 21.462022 | AI13: =AVERAGE(L13,M13,N13) -> 24.333333 | AJ13: =AVERAGE((T13-1)/(Scales!$B$36-1)*100,R13,U13) -> 66.666667 | AK13: =AVERAGE(Z13,S13/Scales!$B$34*100) -> 87.5 | AL13: =MAX(W13*Scales!$B$16,X13*Scales!$B$17) -> 0 | AM13: =AVERAGE(AG13,AE13/8*100) -> 27 | AN13: =SUMPRODUCT(AH13:AM13,Scales!$B$11:$G$11)/Scales!$H$11 -> 43.767404 | AO13: =SUMPRODUCT(AH13:AM13,Scales!$B$12:$G$12)/Scales!$H$12 -> 37.827004 | AP13: =SUMPRODUCT(AH13:AM13,Scales!$B$13:$G$13)/Scales!$H$13 -> 34.105273 | AQ13: =IF(AN13>=Scales!$B$38,"High",IF(AN13>=Scales!$B$37,"Medium","Low")) -> Medium | AR13: =IF(D13<>"Confirmed","Low",IF(V13>=2,"High","Medium")) -> Medium | AS13: =IF(AE13=0,"High","Low") -> High | AT13: =IF(OR(AR13="Low",AS13="Low"),"Low",IF(OR(AR13="Medium",AS13="Medium"),"Medium","High")) -> Medium | AU13: =IF(D13="Inferred","Verify the link first (needs direct disclosure)",IF(AQ13="High",IF(AT13="Low","Verify data first","Search alternates now"),IF(AQ13="Medium","Prepare shortlist and monitor","Monitor"))) -> Prepare shortlist and monitor | AV13: =RANK(AN13,$AN$2:$AN$25) -> 12 | AW13: =RANK(AO13,$AO$2:$AO$25) -> 13 | AX13: =RANK(AP13,$AP$2:$AP$25) -> 17
... A25: ORG-176 | B25: HarborSense Electronics Ltd. | C25: Tier-1 | D25: Confirmed | E25: Z05 | F25: =MATCH(A25,Indicators!$A$2:$A$31,0) -> 11 | G25: =IF(INDEX(Indicators!$C$2:$C$31,$F25)="","",INDEX(Indicators!$C$2:$C$31,$F25)) -> 2.24 | H25: =IF(INDEX(Indicators!$D$2:$D$31,$F25)="","",INDEX(Indicators!$D$2:$D$31,$F25)) -> 2.33 | I25: =IF(INDEX(Indicators!$E$2:$E$31,$F25)="","",INDEX(Indicators!$E$2:$E$31,$F25)) -> 81.9 | J25: =IF(INDEX(Indicators!$F$2:$F$31,$F25)="","",INDEX(Indicators!$F$2:$F$31,$F25)) -> -0.9 | K25: =IF(INDEX(Indicators!$G$2:$G$31,$F25)="","",INDEX(Indicators!$G$2:$G$31,$F25)) -> 27 | L25: =IF(INDEX(Indicators!$H$2:$H$31,$F25)="","",INDEX(Indicators!$H$2:$H$31,$F25)) -> 31 | M25: =IF(INDEX(Indicators!$I$2:$I$31,$F25)="","",INDEX(Indicators!$I$2:$I$31,$F25)) -> 23 | N25: =IF(INDEX(Indicators!$J$2:$J$31,$F25)="","",INDEX(Indicators!$J$2:$J$31,$F25)) -> 19 | O25: 0 | P25: 0 | Q25: 1 | R25: 20 | S25: 12 | T25: 1 | U25: 0 | V25: 2 | W25: =IF(E25="Z01",1,0) -> 0 | X25: 0 | Y25: =O25*Scales!$B$21+P25*Scales!$B$22+Q25*Scales!$B$23 -> 416 | Z25: =Y25/Scales!$B$24*100 -> 26.666667 | AA25: =IF(G25="","",(Scales!$C$4-G25)/(Scales!$C$4-Scales!$B$4)*100) -> 15.183246 | AB25: =IF(H25="","",(H25-Scales!$B$5)/(Scales!$C$5-Scales!$B$5)*100) -> 21.451613 | AC25: =(Scales!$C$6-I25)/(Scales!$C$6-Scales!$B$6)*100 -> 64.052288 | AD25: =(Scales!$C$7-J25)/(Scales!$C$7-Scales!$B$7)*100 -> 18.137255 | AE25: =8-COUNT(G25:N25) -> 0 | AF25: =IF(D25="Inferred",100,IF(V25>=2,0,50)) -> 0 | AG25: =IF(K25="",100,K25) -> 27 | AH25: =IF(AA25="",AVERAGE(AC25,AD25),AVERAGE(AA25,AB25,AC25,AD25)) -> 29.7061 | AI25: =AVERAGE(L25,M25,N25) -> 24.333333 | AJ25: =AVERAGE((T25-1)/(Scales!$B$36-1)*100,R25,U25) -> 6.6666667 | AK25: =AVERAGE(Z25,S25/Scales!$B$34*100) -> 50.833333 | AL25: =MAX(W25*Scales!$B$16,X25*Scales!$B$17) -> 0 | AM25: =AVERAGE(AG25,AE25/8*100) -> 13.5 | AN25: =SUMPRODUCT(AH25:AM25,Scales!$B$11:$G$11)/Scales!$H$11 -> 20.56622 | AO25: =SUMPRODUCT(AH25:AM25,Scales!$B$12:$G$12)/Scales!$H$12 -> 20.839906 | AP25: =SUMPRODUCT(AH25:AM25,Scales!$B$13:$G$13)/Scales!$H$13 -> 21.88683 | AQ25: =IF(AN25>=Scales!$B$38,"High",IF(AN25>=Scales!$B$37,"Medium","Low")) -> Low | AR25: =IF(D25<>"Confirmed","Low",IF(V25>=2,"High","Medium")) -> High | AS25: =IF(AE25=0,"High","Low") -> High | AT25: =IF(OR(AR25="Low",AS25="Low"),"Low",IF(OR(AR25="Medium",AS25="Medium"),"Medium","High")) -> High | AU25: =IF(D25="Inferred","Verify the link first (needs direct disclosure)",IF(AQ25="High",IF(AT25="Low","Verify data first","Search alternates now"),IF(AQ25="Medium","Prepare shortlist and monitor","Monitor"))) -> Monitor | AV25: =RANK(AN25,$AN$2:$AN$25) -> 24 | AW25: =RANK(AO25,$AO$2:$AO$25) -> 24 | AX25: =RANK(AP25,$AP$2:$AP$25) -> 24
A27: Blue = inputs taken from the workbook sheets or from the network map in the tiering workbook. Everything else is a formula.

Sheet Scales
A1: Scales, weights and inputs (blue cells can be edited)
A3: Measure | B3: Lowest in sheet | C3: Highest in sheet | D3: Which end is riskier
A4: Current ratio | B4: =MIN(Indicators!C2:C31) -> 0.62 | C4: =MAX(Indicators!C2:C31) -> 2.53 | D4: Lower = riskier
A5: Net debt / EBITDA | B5: =MIN(Indicators!D2:D31) -> 1 | C5: =MAX(Indicators!D2:D31) -> 7.2 | D5: Higher = riskier
A6: Shipment timeliness, 3M avg (%) | B6: =MIN(Indicators!E2:E31) -> 76.4 | C6: =MAX(Indicators!E2:E31) -> 91.7 | D6: Lower = riskier
A7: Timeliness change, Jan to latest (pts) | B7: =MIN(Indicators!F2:F31) -> -17.6 | C7: =MAX(Indicators!F2:F31) -> 2.8 | D7: Lower (more negative) = riskier
A9: Dimension weights (%)
A10: Weight set | B10: Financial & operational health | C10: Location & systemic exposure | D10: Network dependence & upstream concentration | E10: Business criticality & substitutability | F10: Dynamic external threats | G10: Information gap & assurance | H10: Total
A11: Active weights (used in Scorecard) | B11: 20 | C11: 15 | D11: 30 | E11: 15 | F11: 10 | G11: 10 | H11: =SUM(B11:G11) -> 100
A12: Test A: equal weights | B12: 1 | C12: 1 | D12: 1 | E12: 1 | F12: 1 | G12: 1 | H12: =SUM(B12:G12) -> 6
A13: Test B: health and location led | B13: 30 | C13: 20 | D13: 15 | E13: 10 | F13: 10 | G13: 15 | H13: =SUM(B13:G13) -> 100
A15: Event severity levels (0-100). These are assumptions, editable
A16: Zone-level watch, no damage confirmed (EV-001) | B16: 40
A17: Supplier-specific adverse report, production continues (EV-003) | B17: 60
A18: Confirmed disruption of the supplier's facility (none in data) | B18: 100
A20: Product revenue, USD m (Business Context sheet)
A21: P1 DriveCore industrial inverter | B21: 624
A22: P2 ChargeBridge charging power unit | B22: 520
A23: P3 StoreLink storage control cabinet | B23: 416
A24: Total | B24: =SUM(B21:B23) -> 1560
A26: Weeks to qualify a replacement (Components Context sheet)
A27: M10 Standard power assembly | B27: 16
A28: M20 High-voltage power assembly | B28: 16
A29: C10 Control board | B29: 12
A30: C20 DC-link capacitor | B30: 8
A31: H10 Protective housing | B31: 4
A32: H20 Cooling assembly | B32: 6
A33: B10 Battery-monitoring board | B33: 12
A34: Longest | B34: =MAX(B27:B33) -> 16
A36: Most Tier-1 suppliers hit by one node | B36: =MAX(Calc!T2:T25) -> 3
A37: Risk band: 'Medium' starts at (1/3 point of the 24 suppliers) | B37: =PERCENTILE(Calc!AN2:AN25,1/3) -> 41.525992
A38: Risk band: 'High' starts at (2/3 point of the 24 suppliers) | B38: =PERCENTILE(Calc!AN2:AN25,2/3) -> 54.289898

Sheet Events
A1: Event | B1: Date | C1: Headline | D1: Decision | E1: Matched to | F1: Severity level used | G1: Severity (0-100) | H1: Why | I1: What to verify
A2: EV-001 | B2: 2025-09-23 | C2: East Delta flood watch | D2: Matched: watch only | E2: Every Z01 supplier in the network: IonPeak, Jade PC, Orion, Umber, Verdant | F2: Zone-level watch | G2: =Scales!B16 -> 40 | H2: Event names zone Z01. No damage or shutdown confirmed. | I2: Flood readiness at Z01 suppliers.
A3: EV-002 | B3: 2025-09-23 | C3: Trade-wire repeats flood watch | D3: Duplicate: count once | E3: (same as EV-001) | F3: None | G3: =0 -> 0 | H3: Same source family WX-0923; no independent evidence. | I3: None.
A4: EV-003 | B4: 2025-09-24 | C4: Meridian financing pressure | D4: Matched: supplier-specific | E4: Meridian Dielectrics | F4: Supplier-specific adverse report | G4: =Scales!B17 -> 60 | H4: Name matches exactly; production continues. | I4: Credit position; Delta Capacitor exposure.
A5: EV-004 | B5: 2025-09-25 | C5: Ion Peak Trading insolvency | D5: No match: different company | E5: none | F5: None | G5: =0 -> 0 | H5: Ion Peak Trading is a broker, not IonPeak Semiconductor (DOC-077). | I5: None.
A6: EV-005 | B6: 2025-09-26 | C6: Archived port strike reposted | D6: Stale: ignore | E6: none | F6: None | G6: =0 -> 0 | H6: Effective 2023-11-03; dispute ended in 2023. | I6: None.
A7: EV-007 | B7: 2025-09-27 | C7: Jade head office relocation | D7: Matched: no production impact | E7: Jade (head office only) | F7: None | G7: =0 -> 0 | H7: Administrative move; production stays at East Delta site. | I7: None, unless disruption is reported.
A8: EV-009 | B8: 2025-09-29 | C8: Delta packaging allegation corrected | D8: No match: different company | E8: none | F8: None | G8: =0 -> 0 | H8: About Delta Consumer Plastics, not Delta Capacitor Works. | I8: None.
A9: EV-010 | B9: 2025-09-30 | C9: Gulf Arc port congestion | D9: Cannot match: not enough data | E9: none | F9: None | G9: =0 -> 0 | H9: No supplier, facility or zone in the workbook is tied to Gulf Arc. | I9: Which suppliers ship via Gulf Arc.
A11: D5 uses the highest matched severity per supplier. Severity levels are assumptions (editable on Scales); the data gives no severity scale. EV-006 and EV-008 are absent from the sheet.

Sheet Sensitivity
A1: Entity ID | B1: Legal name | C1: Rank: active weights | D1: Rank: equal weights | E1: Rank: health and location led | F1: Biggest move
A2: =Calc!A2 -> ORG-453 | B2: =Calc!B2 -> Jade Printed Circuits Ltd. | C2: =Calc!AV2 -> 1 | D2: =Calc!AW2 -> 3 | E2: =Calc!AX2 -> 4 | F2: =MAX(C2:E2)-MIN(C2:E2) -> 3
A3: =Calc!A3 -> ORG-455 | B3: =Calc!B3 -> Umber Silicon Carbide Ltd. | C3: =Calc!AV3 -> 2 | D3: =Calc!AW3 -> 1 | E3: =Calc!AX3 -> 1 | F3: =MAX(C3:E3)-MIN(C3:E3) -> 1
A4: =Calc!A4 -> ORG-736 | B4: =Calc!B4 -> Verdant Process Gases Ltd. | C4: =Calc!AV4 -> 3 | D4: =Calc!AW4 -> 2 | E4: =Calc!AX4 -> 2 | F4: =MAX(C4:E4)-MIN(C4:E4) -> 1
A5: =Calc!A5 -> ORG-439 | B5: =Calc!B5 -> IonPeak Semiconductor Ltd. | C5: =Calc!AV5 -> 4 | D5: =Calc!AW5 -> 4 | E5: =Calc!AX5 -> 5 | F5: =MAX(C5:E5)-MIN(C5:E5) -> 1
A6: =Calc!A6 -> ORG-708 | B6: =Calc!B6 -> Orion Ceramics Ltd. | C6: =Calc!AV6 -> 5 | D6: =Calc!AW6 -> 6 | E6: =Calc!AX6 -> 6 | F6: =MAX(C6:E6)-MIN(C6:E6) -> 1
A7: =Calc!A7 -> ORG-210 | B7: =Calc!B7 -> Meridian Dielectrics Ltd. | C7: =Calc!AV7 -> 6 | D7: =Calc!AW7 -> 5 | E7: =Calc!AX7 -> 3 | F7: =MAX(C7:E7)-MIN(C7:E7) -> 3
A8: =Calc!A8 -> ORG-873 | B8: =Calc!B8 -> Warden Copper Foil Ltd. | C8: =Calc!AV8 -> 7 | D8: =Calc!AW8 -> 7 | E8: =Calc!AX8 -> 7 | F8: =MAX(C8:E8)-MIN(C8:E8) -> 0
A9: =Calc!A9 -> ORG-179 | B9: =Calc!B9 -> Xenon Resin Ltd. | C9: =Calc!AV9 -> 8 | D9: =Calc!AW9 -> 8 | E9: =Calc!AX9 -> 8 | F9: =MAX(C9:E9)-MIN(C9:E9) -> 0
A10: =Calc!A10 -> ORG-942 | B10: =Calc!B10 -> Lumen Magnetics Ltd. | C10: =Calc!AV10 -> 9 | D10: =Calc!AW10 -> 10 | E10: =Calc!AX10 -> 9 | F10: =MAX(C10:E10)-MIN(C10:E10) -> 1
A11: =Calc!A11 -> ORG-520 | B11: =Calc!B11 -> Yarrow Specialty Minerals Ltd. | C11: =Calc!AV11 -> 10 | D11: =Calc!AW11 -> 9 | E11: =Calc!AX11 -> 11 | F11: =MAX(C11:E11)-MIN(C11:E11) -> 2
A12: =Calc!A12 -> ORG-119 | B12: =Calc!B12 -> Cobalt Control Electronics Ltd. | C12: =Calc!AV12 -> 11 | D12: =Calc!AW12 -> 11 | E12: =Calc!AX12 -> 10 | F12: =MAX(C12:E12)-MIN(C12:E12) -> 1
A13: =Calc!A13 -> ORG-728 | B13: =Calc!B13 -> Kestrel Microdevices Ltd. | C13: =Calc!AV13 -> 12 | D13: =Calc!AW13 -> 13 | E13: =Calc!AX13 -> 17 | F13: =MAX(C13:E13)-MIN(C13:E13) -> 5
... A25: =Calc!A25 -> ORG-176 | B25: =Calc!B25 -> HarborSense Electronics Ltd. | C25: =Calc!AV25 -> 24 | D25: =Calc!AW25 -> 24 | E25: =Calc!AX25 -> 24 | F25: =MAX(C25:E25)-MIN(C25:E25) -> 0
